Workbook
Name __123Graph_A: '[1]1.6 TRS Data'!#REF!
Name __123Graph_A: '[1]1.6 TRS Data'!#REF!
Name __123Graph_A: '[1]1.6 TRS Data'!#REF!
Name __123Graph_B: '[1]1.6 TRS Data'!#REF!
Name __123Graph_B: '[1]1.6 TRS Data'!#REF!
Name __123Graph_B: '[1]1.6 TRS Data'!#REF!
Name __123Graph_LBL_A: '[1]1.6 TRS Data'!#REF!
Name __123Graph_LBL_A: '[1]1.6 TRS Data'!#REF!
Name __123Graph_LBL_A: '[1]1.6 TRS Data'!#REF!
Name __123Graph_X: '[1]1.6 TRS Data'!#REF!
Name __123Graph_X: '[1]1.6 TRS Data'!#REF!
Name __123Graph_X: '[1]1.6 TRS Data'!#REF!
Name __kpn1: [2]Главн!$D$46
Name __kpn2: [2]Главн!$E$46
Name __kpn3: [2]Главн!$F$46
Name __kpn4: [2]Главн!$G$46
Name __kpn5: [2]Главн!$H$46
Name __kpn6: [2]Главн!$I$46
Name __kpn7: [2]Главн!$J$46
Name __kpn8: [2]Главн!$K$46
Name __nds1: [2]Главн!$D$42
Name __nds2: [2]Главн!$E$42
Name __nds3: [2]Главн!$F$42
Name __nds4: [2]Главн!$G$42
Name __nds5: [2]Главн!$H$42
Name __nds6: [2]Главн!$I$42
Name _kpn1: [2]Главн!$D$46
Name _kpn1: [2]Главн!$D$46
Name _kpn1: [2]Главн!$D$46
Name _kpn1: [2]Главн!$D$46
Name _kpn2: [2]Главн!$E$46
Name _kpn2: [2]Главн!$E$46
Name _kpn2: [2]Главн!$E$46
Name _kpn2: [2]Главн!$E$46
Name _kpn3: [2]Главн!$F$46
Name _kpn3: [2]Главн!$F$46
Name _kpn3: [2]Главн!$F$46
Name _kpn3: [2]Главн!$F$46
Name _kpn4: [2]Главн!$G$46
Name _kpn4: [2]Главн!$G$46
Name _kpn4: [2]Главн!$G$46
Name _kpn4: [2]Главн!$G$46
Name _kpn5: [2]Главн!$H$46
Name _kpn5: [2]Главн!$H$46
Name _kpn5: [2]Главн!$H$46
Name _kpn5: [2]Главн!$H$46
Name _kpn6: [2]Главн!$I$46
Name _kpn6: [2]Главн!$I$46
Name _kpn6: [2]Главн!$I$46
Name _kpn6: [2]Главн!$I$46
Name _kpn7: [2]Главн!$J$46
Name _kpn7: [2]Главн!$J$46
Name _kpn7: [2]Главн!$J$46
Name _kpn7: [2]Главн!$J$46
Name _kpn8: [2]Главн!$K$46
Name _kpn8: [2]Главн!$K$46
Name _kpn8: [2]Главн!$K$46
Name _kpn8: [2]Главн!$K$46
Name _nds1: [2]Главн!$D$42
Name _nds1: [2]Главн!$D$42

Sheet Panel
A2: Строительство ГЭС -5 МВТ
A6: Панель управления
A7: Изменение тарифа | B7: 0
A8: Изменение фонда оплаты труда | B8: 0
A9: Изменение стоимости строительно-монтажных работ | B9: 0
A10: Изменение стоимости производственного оборудования | B10: 0
A12: Результат
A13: Ставка дисконтирования, % | B13: ='ОСДП'!B7 -> 0.097271767
A14: NPV | B14: ='ОСДП'!B19 -> 2605678
A16: Срок окупаемости
A17: не дисконтированный, лет | B17: ='ОСДП'!B24 -> 7.3984916
A18: дисконтированный, лет | B18: ='ОСДП'!B25 -> 9.7048422
A20: Ставка амортизации по основным средствам:
A21: Группы основных средств: | B21: Срок службы | C21: Ед. изм | D21: Ставка, %
A22: Здания и сооружения | B22: 15 | C22: лет | D22: =1/B22 -> 0.066666667
A23: Производственное оборудование | B23: 15 | C23: лет | D23: =1/B23 -> 0.066666667
A25: Ставки налогов на коммерческие объекты | B25: 2026
A26: НДС | B26: 0.16
A27: Корпоративный подоходный налог | B27: 0.2
A29: Для расчета социального налога и обязательных отчислений в бюджет (на 2026 год):
A30: Минимальная заработная плата | B30: 85000 | C30: Тенге
A31: Месячный расчетный показатель | B31: 4325 | C31: Тенге
A32: Ставка социального налога | B32: 0.06
A33: Ставка социального страхования | B33: 0.05
A34: Минимальный размер соц.отч. | B34: =B30*B33 -> 4250 | C34: Тенге
A35: Максимальный размер соц.отч. | B35: =7*B30*B33 -> 29750 | C35: Тенге
A36: Минимальный размер соц.налога | B36: =B30*B32 -> 5100 | C36: Тенге
A37: Ставка по обязательным пенсионным отчислениям | B37: 0.1
A38: Ставка Индивидуального Подоходного Налога | B38: 0.1 | C38: используется после выплаты обязательных пенсионных отчислений и минимальной заработной платы
A39: Ставка взносов на ОСМС в 2018-2019 гг. | B39: 0.015
A40: Ставка взносов на ОСМС в 2026-2027 гг. | B40: 0.02
A41: Ставка взносов на ОСМС в 2028 г. и далее | B41: 0.03
A43: Инфляция | B43: 0.117

Sheet Инвестиции
A1: =Panel!A1
A2: =Panel!A2 -> Строительство ГЭС -5 МВТ
J3: оборудование | K3: =69000*3*335 -> 69345000
A4: ИНВЕСТИЦИОННЫЕ ЗАТРАТЫ (ВКЛ. НДС) | J4: цеха | K4: =15000000*6 -> 90000000
A6: в тыс. тенге, если не указано иное
A7: № | B7: Наименование затрат | C7: Сумма, вкл. НДС | D7: Доля, % | E7: Источники финансирования | G7: Источники финансирования, %
E8: Собственные средства | F8: Заемные средства | G8: Собственные средства | H8: Заемные средства
A9: 1 | B9: ПИР | C9: ='Смета'!G29*(1+Panel!$B$26)*(1+2%) -> 107875.75 | D9: =C9/$C$15 -> 0.035835299 | E9: =C9*G9 -> 72379.946 | F9: =C9*H9 -> 35495.805 | G9: =100%-H9 -> 0.67095659 | H9: 0.32904341
A10: 2 | B10: Экспертиза | C10: ='Смета'!G30*(1+Panel!$B$26)*(1+2%) -> 2363.5888 | D10: =C10/$C$15 -> 0.00078516174 | E10: =C10*G10 -> 2363.5888 | F10: =C10*H10 -> 0 | G10: 1 | H10: =100%-G10 -> 0
A11: 3 | B11: Cтроительно-монтажные работы | C11: ='A-0'!AM10 -> 969225.54 | D11: =C11/$C$15 -> 0.32196751 | E11: =C11*G11 -> 570489.22 | F11: =C11*H11 -> 398736.33 | G11: 0.58860316 | H11: =100%-G11 -> 0.41139684
A12: 4 | B12: Производственное оборудование | C12: ='A-0'!AM11 -> 1883220.5 | D12: =C12/$C$15 -> 0.62558796 | E12: =C12*G12 -> 0 | F12: =C12*H12 -> 1883220.5 | G12: 0 | H12: =100%-G12 -> 1
A13: 5 | B13: Технический надзор | C13: ='A-0'!AM12 -> 41930.678 | D13: =C13/$C$15 -> 0.013928973 | E13: =C13*G13 -> 8386.1356 | F13: =C13*H13 -> 33544.542 | G13: 0.2 | H13: =100%-G13 -> 0.8
A14: 6 | B14: Авторский надзор | C14: ='A-0'!AM13 -> 5704.8542 | D14: =C14/$C$15 -> 0.0018950983 | E14: =C14*G14 -> 1140.9708 | F14: =C14*H14 -> 4563.8833 | G14: 0.2 | H14: =100%-G14 -> 0.8
B15: Итого | C15: =SUM(C9:C14) -> 3010321 | D15: =SUM(D9:D14) -> 1 | E15: =SUM(E9:E14) -> 654759.86 | F15: =SUM(F9:F14) -> 2355561.1
F19: =F15-750000 -> 1605561.1 | G19: 0.67023326
F20: 750000 | G20: 0.32976674

Sheet A-0
A1: =Panel!A1 | V1: =SUM(V11:AG11) -> 784675.22 | W1: =SUM(AH11:AL11) -> 0
A2: =Panel!A2 -> Строительство ГЭС -5 МВТ
A4: ГРАФИК ФИНАНСИРОВАНИЯ
A6: в тыс. тенге, если не указано иное
A7: № | B7: Наименование | C7: 2018 | O7: 2026 | AA7: 2027 | AM7: Итого
C8: янв | D8: фев | E8: мар | F8: апр | G8: май | H8: июн | I8: июл | J8: авг | K8: сен | L8: окт | M8: ноя | N8: дек | O8: янв | P8: фев | Q8: мар | R8: апр | S8: май | T8: июн | U8: июл | V8: авг | W8: сен | X8: окт | Y8: ноя | Z8: дек | AA8: янв | AB8: фев | AC8: мар | AD8: апр | AE8: май | AF8: июн | AG8: июл | AH8: авг | AI8: сен | AJ8: окт | AK8: ноя | AL8: дек
A9: 1 | B9: ПИР | I9: =H9 | O9: ='Инвестиции'!F9 -> 35495.805 | AM9: =SUM(C9:AL9) -> 35495.805
A10: 2 | B10: ='Инвестиции'!B11 -> Cтроительно-монтажные работы | I10: =H10 | O10: =(('Смета'!D27)/12)*(1+Panel!$B$26)*(1+2.002%)*(1+Panel!$B$9) -> 80768.795 | P10: =O10 -> 80768.795 | Q10: =P10 -> 80768.795 | R10: =Q10 -> 80768.795 | S10: =R10 -> 80768.795 | T10: =S10 -> 80768.795 | U10: =T10 -> 80768.795 | V10: =U10 -> 80768.795 | W10: =V10 -> 80768.795 | ... Z10: =Y10 -> 80768.795 | AM10: =SUM(C10:AL10) -> 969225.54
A11: 3 | B11: ='Инвестиции'!B12 -> Производственное оборудование | O11: =(('Смета'!E27)/12)*(1+Panel!$B$26)*(1+2%)*(1+Panel!$B$10) -> 156935.04 | P11: =O11 -> 156935.04 | Q11: =P11 -> 156935.04 | R11: =Q11 -> 156935.04 | S11: =R11 -> 156935.04 | T11: =S11 -> 156935.04 | U11: =T11 -> 156935.04 | V11: =U11 -> 156935.04 | W11: =V11 -> 156935.04 | ... Z11: =Y11 -> 156935.04 | AM11: =SUM(C11:AL11) -> 1883220.5
A12: 4 | B12: ='Инвестиции'!B13 -> Технический надзор | O12: =(('Смета'!G32)/12)*(1+Panel!$B$26)*(1+2%)*(1+Panel!$B$9) -> 3494.2232 | P12: =O12 -> 3494.2232 | Q12: =P12 -> 3494.2232 | R12: =Q12 -> 3494.2232 | S12: =R12 -> 3494.2232 | T12: =S12 -> 3494.2232 | U12: =T12 -> 3494.2232 | V12: =U12 -> 3494.2232 | W12: =V12 -> 3494.2232 | ... Z12: =Y12 -> 3494.2232 | AM12: =SUM(C12:AL12) -> 41930.678
A13: 5 | B13: ='Инвестиции'!B14 -> Авторский надзор | I13: =H13 | O13: =(('Смета'!G34)/12)*(1+Panel!$B$26)*(1+2%)*(1+Panel!$B$9) -> 475.40451 | P13: =O13 -> 475.40451 | Q13: =P13 -> 475.40451 | R13: =Q13 -> 475.40451 | S13: =R13 -> 475.40451 | T13: =S13 -> 475.40451 | U13: =T13 -> 475.40451 | V13: =U13 -> 475.40451 | W13: =V13 -> 475.40451 | ... Z13: =Y13 -> 475.40451 | AM13: =SUM(C13:AL13) -> 5704.8542
B14: ИТОГО | C14: =SUM(C10:C13) -> 0 | D14: =SUM(D10:D13) -> 0 | E14: =SUM(E10:E13) -> 0 | F14: =SUM(F10:F13) -> 0 | G14: =SUM(G10:G13) -> 0 | H14: =SUM(H10:H13) -> 0 | I14: =SUM(I10:I13) -> 0 | J14: =SUM(J10:J13) -> 0 | ... AM14: =SUM(AM10:AM13) -> 2900081.6
B16: Собственные средства | C16: =SUM(C17:C21) -> 0 | D16: =SUM(D17:D21) -> 0 | E16: =SUM(E17:E21) -> 0 | F16: =SUM(F17:F21) -> 0 | G16: =SUM(G17:G21) -> 0 | H16: =SUM(H17:H21) -> 0 | I16: =SUM(I17:I21) -> 0 | J16: =SUM(J17:J21) -> 0 | ... AL16: =SUM(AL17:AL21) -> 0 | AM16: =SUM(E16:AL16) -> 580016.32
B17: ПИР | AM17: =SUM(E17:AL17) -> 0
B18: Cтроительно-монтажные работы | O18: =O10*'Инвестиции'!$G$11 -> 47540.768 | P18: =P10*'Инвестиции'!$G$11 -> 47540.768 | Q18: =Q10*'Инвестиции'!$G$11 -> 47540.768 | R18: =R10*'Инвестиции'!$G$11 -> 47540.768 | S18: =S10*'Инвестиции'!$G$11 -> 47540.768 | T18: =T10*'Инвестиции'!$G$11 -> 47540.768 | U18: =U10*'Инвестиции'!$G$11 -> 47540.768 | V18: =V10*'Инвестиции'!$G$11 -> 47540.768 | ... Z18: =Z10*'Инвестиции'!$G$11 -> 47540.768 | AM18: =SUM(E18:AL18) -> 570489.22
B19: Производственное оборудование | O19: =O11*'Инвестиции'!$G$12 -> 0 | P19: =P11*'Инвестиции'!$G$12 -> 0 | Q19: =Q11*'Инвестиции'!$G$12 -> 0 | R19: =R11*'Инвестиции'!$G$12 -> 0 | S19: =S11*'Инвестиции'!$G$12 -> 0 | T19: =T11*'Инвестиции'!$G$12 -> 0 | U19: =U11*'Инвестиции'!$G$12 -> 0 | V19: =V11*'Инвестиции'!$G$12 -> 0 | ... Z19: =Z11*'Инвестиции'!$G$12 -> 0 | AM19: =SUM(E19:AL19) -> 0
B20: Технический надзор | O20: =O12*'Инвестиции'!$G$13 -> 698.84463 | P20: =P12*'Инвестиции'!$G$13 -> 698.84463 | Q20: =Q12*'Инвестиции'!$G$13 -> 698.84463 | R20: =R12*'Инвестиции'!$G$13 -> 698.84463 | S20: =S12*'Инвестиции'!$G$13 -> 698.84463 | T20: =T12*'Инвестиции'!$G$13 -> 698.84463 | U20: =U12*'Инвестиции'!$G$13 -> 698.84463 | V20: =V12*'Инвестиции'!$G$13 -> 698.84463 | ... Z20: =Z12*'Инвестиции'!$G$13 -> 698.84463 | AM20: =SUM(E20:AL20) -> 8386.1356
B21: Авторский надзор | O21: =O13*'Инвестиции'!$G$14 -> 95.080902 | P21: =P13*'Инвестиции'!$G$14 -> 95.080902 | Q21: =Q13*'Инвестиции'!$G$14 -> 95.080902 | R21: =R13*'Инвестиции'!$G$14 -> 95.080902 | S21: =S13*'Инвестиции'!$G$14 -> 95.080902 | T21: =T13*'Инвестиции'!$G$14 -> 95.080902 | U21: =U13*'Инвестиции'!$G$14 -> 95.080902 | V21: =V13*'Инвестиции'!$G$14 -> 95.080902 | ... Z21: =Z13*'Инвестиции'!$G$14 -> 95.080902 | AM21: =SUM(E21:AL21) -> 1140.9708
B22: Заемные средства | C22: =SUM(C23:C27) -> 0 | D22: =SUM(D23:D27) -> 0 | E22: =SUM(E23:E27) -> 0 | F22: =SUM(F23:F27) -> 0 | G22: =SUM(G23:G27) -> 0 | H22: =SUM(H23:H27) -> 0 | I22: =SUM(I23:I27) -> 0 | J22: =SUM(J23:J27) -> 0 | ... AL22: =SUM(AL23:AL27) -> 0 | AM22: =SUM(E22:AL22) -> 2355561.1
B23: ПИР | O23: =O9 -> 35495.805 | P23: =P9 | Q23: =Q9 | R23: =R9 | S23: =S9 | T23: =T9 | U23: =U9 | V23: =V9 | ... Z23: =Z9 | AM23: =SUM(E23:AL23) -> 35495.805
B24: Cтроительно-монтажные работы | O24: =O10*'Инвестиции'!$H$11 -> 33228.027 | P24: =P10*'Инвестиции'!$H$11 -> 33228.027 | Q24: =Q10*'Инвестиции'!$H$11 -> 33228.027 | R24: =R10*'Инвестиции'!$H$11 -> 33228.027 | S24: =S10*'Инвестиции'!$H$11 -> 33228.027 | T24: =T10*'Инвестиции'!$H$11 -> 33228.027 | U24: =U10*'Инвестиции'!$H$11 -> 33228.027 | V24: =V10*'Инвестиции'!$H$11 -> 33228.027 | ... Z24: =Z10*'Инвестиции'!$H$11 -> 33228.027 | AM24: =SUM(E24:AL24) -> 398736.33
B25: Производственное оборудование | O25: =O11*'Инвестиции'!$H$12 -> 156935.04 | P25: =P11*'Инвестиции'!$H$12 -> 156935.04 | Q25: =Q11*'Инвестиции'!$H$12 -> 156935.04 | R25: =R11*'Инвестиции'!$H$12 -> 156935.04 | S25: =S11*'Инвестиции'!$H$12 -> 156935.04 | T25: =T11*'Инвестиции'!$H$12 -> 156935.04 | U25: =U11*'Инвестиции'!$H$12 -> 156935.04 | V25: =V11*'Инвестиции'!$H$12 -> 156935.04 | ... Z25: =Z11*'Инвестиции'!$H$12 -> 156935.04 | AM25: =SUM(E25:AL25) -> 1883220.5
B26: Технический надзор | O26: =O12*'Инвестиции'!$H$13 -> 2795.3785 | P26: =P12*'Инвестиции'!$H$13 -> 2795.3785 | Q26: =Q12*'Инвестиции'!$H$13 -> 2795.3785 | R26: =R12*'Инвестиции'!$H$13 -> 2795.3785 | S26: =S12*'Инвестиции'!$H$13 -> 2795.3785 | T26: =T12*'Инвестиции'!$H$13 -> 2795.3785 | U26: =U12*'Инвестиции'!$H$13 -> 2795.3785 | V26: =V12*'Инвестиции'!$H$13 -> 2795.3785 | ... Z26: =Z12*'Инвестиции'!$H$13 -> 2795.3785 | AM26: =SUM(E26:AL26) -> 33544.542
B27: Авторский надзор | O27: =O13*'Инвестиции'!$H$14 -> 380.32361 | P27: =P13*'Инвестиции'!$H$14 -> 380.32361 | Q27: =Q13*'Инвестиции'!$H$14 -> 380.32361 | R27: =R13*'Инвестиции'!$H$14 -> 380.32361 | S27: =S13*'Инвестиции'!$H$14 -> 380.32361 | T27: =T13*'Инвестиции'!$H$14 -> 380.32361 | U27: =U13*'Инвестиции'!$H$14 -> 380.32361 | V27: =V13*'Инвестиции'!$H$14 -> 380.32361 | ... Z27: =Z13*'Инвестиции'!$H$14 -> 380.32361 | AM27: =SUM(E27:AL27) -> 4563.8833

Sheet Смета
C1: =Panel!A2 -> Строительство ГЭС -5 МВТ
C2: (наименование организации)
A3: "Согласован"
A5: Сводный сметный расчет в сумме | F5: =G40 -> 3010321 | G5: тыс.тенге
B6: в том числе:
B7: налог на добавленную стоимость (НДС) | F7: =G39 -> 415216.68 | G7: тыс.тенге
B11: (ссылка на документ о согласовании)
A13: "____"_______________ 20 г.
B15: СВОДНЫЙ СМЕТНЫЙ РАСЧЕТ
B17: =Panel!A2 -> Строительство ГЭС -5 МВТ
B18: (наименование стройки)
A20: Составлен в текущих ценах по состоянию на 2 квартал 2018 г.
A21: № п/п | B21: № смет и расчетов | C21: Наименование работ и затрат | D21: Сметная стоимость, тысяч тенге | G21: Всего, тысяч тенге
D22: строительно-монтажных работ | E22: оборудования, мебели и инвентаря | F22: прочих затрат
A23: 1 | B23: 2 | C23: 3 | D23: 4 | E23: 5 | F23: 6 | G23: 7
A25: 1 | C25: Сметный расчет стоимости строительства в ценах 2001г. | D25: =423355.51+6622.34-20467.84-176502+18416.2 -> 251424.21 | E25: =336182.14-22553.74-86297.5-213914.81+456698.5+18416.2 -> 488530.79 | G25: =D25+E25+F25 -> 739955
B27: 1 | C27: Итого по сметному расчету в текущих ценах 2026 г К=3,258 | D27: =D25*3.258 -> 819140.08 | E27: =E25*3.258 -> 1591633.3 | G27: =D27+E27+F27 -> 2410773.4
A29: 2 | C29: Стоимость ПИР в 2026г | F29: =61172.88+30000 -> 91172.88 | G29: =F29 -> 91172.88
A30: 3 | C30: Стоимость экспертизы в 2026г. | F30: 1997.6241 | G30: =F30 -> 1997.6241
A32: 4 | C32: Затраты Заказчика на управление проектом и технический надзор на 2026 г. -1,47% | F32: =G27*0.0147 -> 35438.369 | G32: =F32 -> 35438.369
A33: 5
A34: 6 | C34: Затраты на осуществление авторского надзора, от стоимости СМР на 2026 г. - 0,2% | F34: =G27*0.002 -> 4821.5468 | G34: =F34 -> 4821.5468
A35: 7
C36: Итого | D36: =D26+D27+D28+F26+F27+F28 -> 819140.08 | E36: =E26+E27+E28 -> 1591633.3 | F36: =F30+F32+F33+F34+F35+F29 -> 133430.42 | G36: =G26+G27+G28+G31+G32+G33+G34+G35+G29+G30 -> 2544203.8
A37: 8 | C37: Резерв средств заказчика на непредвиденные работы и затраты (2%) | D37: =D36*0.02002 -> 16399.184 | E37: =E36*0.02 -> 31832.666 | F37: =F36*0.02 -> 2668.6084 | G37: =F37+E37+D37 -> 50900.459
C38: Итого | D38: =D36+D37 -> 835539.26 | E38: =E36+E37 -> 1623466 | F38: =F36+F37 -> 136099.03 | G38: =G36+G37 -> 2595104.3
A39: 9 | B39: Решения Правительства | C39: Налог на добавленную стоимость, 16% | D39: =D38*Panel!$B$26 -> 133686.28 | E39: =E38*Panel!$B$26 -> 259754.56 | F39: =F38*Panel!$B$26 -> 21775.844 | G39: =G38*Panel!$B$26 -> 415216.68
C40: Всего по сводному сметному расчету | D40: =D38+D39 -> 969225.54 | E40: =E38+E39 -> 1883220.5 | F40: =F38+F39 -> 157874.87 | G40: =G38+G39 -> 3010321
C41: Всего по сводному сметному расчету без ПИР | G41: =G40-G43 -> #REF!
C42: в том чиле по годам:
C43: стоимость ПИР и экспертизы с НДС | G43: =#REF!+#REF!+#REF!+#REF! -> #REF!
C44: стоимость экспертизы с НДС | G44: =#REF!+#REF! -> #REF!
C45: стоимость ПИР с НДС | G45: =#REF!+#REF! -> #REF!
C46: стоимость ПИР 2016 год ТЭО без НДС | G46: 31302
C47: стоимость ПИР 2016 год ТЭО с НДС | G47: =G46+51000/100*12 -> 37422
C48: стоимость ПИР 2017 год РД с НДС | G48: =(G45-G47)/2 -> #REF!
C49: стоимость ПИР 2018 год РД с НДС | G49: =(G45-G47)/2 -> #REF!
C50: 2016 год стоимость строительства | G50: =G62 -> 35759.405
C51: 2017 год стоимость строительства | G51: =#REF! -> #REF!
C52: 2018 год стоимость строительства | G52: =#REF! -> #REF!
...

Sheet Выручка
A1: =Panel!A1
A2: =Panel!A2 -> Строительство ГЭС -5 МВТ
A4: ВАЛОВАЯ ВЫРУЧКА
A6: Тариф на 2026 год по ГЭС-2 и ГЭС-3 | O6: =20.93*(1+Panel!B7) -> 20.93
AO7: 0
A8: Индекс потребительских цен (Электроэнергия, газ и другие виды топлива) в Республике Казахстан | O8: 0.099 | AB8: https://stat.gov.kz/ru/industries/economy/prices/publications/281083/#:~:text=%D0%BF%D1%80%D0%BE%D1%87%D0%B8%D0%B5%20%D0%B2%D0%B8%D0%B4%D1%8B%20%D1%82%D0%BE%D0%BF%D0%BB%D0%B8%D0%B2%D0%B0-,9%2C9,-0%2C814
A10: в тыс.тенге, если не указано иное
A11: № | B11: Наименование | C11: янв | D11: фев | E11: мар | F11: апр | G11: май | H11: июн | I11: июл | J11: авг | K11: сен | L11: окт | M11: ноя | N11: дек | O11: 2026 | P11: янв | Q11: фев | R11: мар | S11: апр | T11: май | U11: июн | V11: июл | W11: авг | X11: сен | Y11: окт | Z11: ноя | AA11: дек | AB11: 2027 | AC11: янв | AD11: фев | AE11: мар | AF11: апр | AG11: май | AH11: июн | AI11: июл | AJ11: авг | AK11: сен | AL11: окт | AM11: ноя | AN11: дек | AO11: 2028 | AP11: 2029 | AQ11: 2030 | AR11: 2031 | AS11: 2032 | AT11: 2033 | AU11: 2034 | AV11: 2035 | AW11: 2036 | AX11: 2037 | AY11: 2038 | AZ11: 2039 | BA11: 2040 | BB11: 2041 | BC11: 2042
A12: 1 | B12: ГЭС-1 на р. | C12: =$O$6*E46*1000 -> 29009.299 | D12: =$O$6*F46*1000 -> 24623.493 | E12: =$O$6*G46*1000 -> 38688.925 | F12: =$O$6*H46*1000 -> 22817.101 | G12: =$O$6*I46*1000 -> 51857.622 | H12: =$O$6*J46*1000 -> 58345.554 | I12: =$O$6*K46*1000 -> 72710.354 | J12: =$O$6*L46*1000 -> 72710.354 | ... N12: =$O$6*P46*1000 -> 29890.895 | O12: =SUM(C12:N12) -> 548578.41 | P12: =C12*(1+$O$8) -> 31881.22 | Q12: =D12*(1+$O$8) -> 27061.219 | R12: =E12*(1+$O$8) -> 42519.129 | S12: =F12*(1+$O$8) -> 25075.994 | T12: =G12*(1+$O$8) -> 56991.526 | U12: =H12*(1+$O$8) -> 64121.763 | V12: =I12*(1+$O$8) -> 79908.679 | W12: =J12*(1+$O$8) -> 79908.679 | ... AA12: =N12*(1+$O$8) -> 32850.093 | AB12: =SUM(P12:AA12) -> 602887.67 | AC12: =P12*(1+$O$8) -> 35037.461 | AD12: =Q12*(1+$O$8) -> 29740.279 | AE12: =R12*(1+$O$8) -> 46728.523 | AF12: =S12*(1+$O$8) -> 27558.518 | AG12: =T12*(1+$O$8) -> 62633.687 | AH12: =U12*(1+$O$8) -> 70469.818 | AI12: =V12*(1+$O$8) -> 87819.638 | AJ12: =W12*(1+$O$8) -> 87819.638 | ... AN12: =AA12*(1+$O$8) -> 36102.253 | AO12: =SUM(AC12:AN12) -> 662573.55 | AP12: =AO12*(1+$O$8) -> 728168.33 | AQ12: =AP12*(1+$O$8) -> 800256.99 | AR12: =AQ12*(1+$O$8) -> 879482.44 | AS12: =AR12*(1+$O$8) -> 966551.2 | AT12: =AS12*(1+$O$8) -> 1062239.8 | AU12: =AT12*(1+$O$8) -> 1167401.5 | AV12: =AU12*(1+$O$8) -> 1282974.2 | AW12: =AV12*(1+$O$8) -> 1409988.7 | ... BC12: =BB12*(1+$O$8) -> 2484287.1
B13: Итого | C13: =SUM(C12) -> 29009.299 | D13: =SUM(D12) -> 24623.493 | E13: =SUM(E12) -> 38688.925 | F13: =SUM(F12) -> 22817.101 | G13: =SUM(G12) -> 51857.622 | H13: =SUM(H12) -> 58345.554 | I13: =SUM(I12) -> 72710.354 | J13: =SUM(J12) -> 72710.354 | ... BC13: =SUM(BC12) -> 2484287.1
A15: ВОДНОЭНЕРГЕТИЧЕСКИЕ РАСЧЕТЫ ГЭС
A16: Технические параметры | D16: Един. | E16: Среднмесячные расходы воды, м3/с | Q16: За год
D17: измер. | E17: I | F17: II | G17: III | H17: IV | I17: V | J17: VI | K17: VII | L17: VIII | M17: IX | N17: X | O17: XI | P17: XII
A18: 0 | D18: 1 | E18: 2 | F18: 3 | G18: 4 | H18: 5 | I18: 6 | J18: 7 | K18: 8 | L18: 9 | M18: 10 | N18: 11 | O18: 12 | P18: 13 | Q18: 14
A19: 1. Продолжительность периода в часах, Т | D19: часы | E19: 744 | F19: 672 | G19: 744 | H19: 720 | I19: 744 | J19: 720 | K19: 744 | L19: 744 | M19: 720 | N19: 744 | O19: 720 | P19: 744 | Q19: =SUM(E19:P19) -> 8760
A20: 2. Расходы воды в реке Qр (р=50%) | D20: м3/с | E20: 3.97 | F20: 3.72 | G20: 5.47 | H20: 6.63 | I20: 14.5 | J20: 24.4 | K20: 28.4 | L20: 21.5 | M20: 11.2 | N20: 7.14 | O20: 5.73 | P20: 4.17 | Q20: =SUM(E20:P20)/12 -> 11.4025
A21: 3. Расходы воды, забираемые на орошение | D21: м3/с | E21: 0 | F21: 0 | G21: 0 | H21: 2.8 | I21: 5.63 | J21: 12.45 | K21: 9.63 | L21: 2.83 | M21: 1.27 | N21: 0 | O21: 0 | P21: 0
A22: 4. Расходы санитарного(эколог.) попуска ΔQэк | D22: м3/с | E22: =0.15*E20 -> 0.5955 | F22: =0.15*F20 -> 0.558 | G22: =0.15*G20 -> 0.8205 | H22: =0.15*H20 -> 0.9945 | I22: =0.15*I20 -> 2.175 | J22: =0.15*J20 -> 3.66 | K22: =0.15*K20 -> 4.26 | L22: =0.15*L20 -> 3.225 | ... P22: =0.15*P20 -> 0.6255
A23: 5. Технолог. потери воды в голове деривации ГЭС Qгэсп | D23: м3/с | E23: =0.01*E20 -> 0.0397 | F23: =0.01*F20 -> 0.0372 | G23: =0.02*G20 -> 0.1094 | H23: =0.02*H20 -> 0.1326 | I23: =0.02*I20 -> 0.29 | J23: =0.02*J20 -> 0.488 | K23: =0.02*K20 -> 0.568 | L23: =0.01*L20 -> 0.215 | M23: =0.01*M20 -> 0.112 | N23: =0.01*N20 -> 0.0714 | O23: =0.01*O20 -> 0.0573 | P23: =0.02*P20 -> 0.0834
A24: 6. Рабочие расходы ГЭС Qгэср | D24: м3/с | E24: =IF(E20-(E21+E22+E23)>11,11,E20-(E21+E22+E23)) -> 3.3348 | F24: =IF(F20-(F21+F22+F23)>11,11,F20-(F21+F22+F23)) -> 3.1248 | G24: =IF(G20-(G21+G22+G23)>11,11,G20-(G21+G22+G23)) -> 4.5401 | H24: =IF(H20-(H21+H22+H23)>11,11,H20-(H21+H22+H23)) -> 2.7029 | I24: =IF(I20-(I21+I22+I23)>11,11,I20-(I21+I22+I23)) -> 6.405 | J24: =IF(J20-(J21+J22+J23)>11,11,J20-(J21+J22+J23)) -> 7.802 | K24: =IF(K20-(K21+K22+K23)>11,11,K20-(K21+K22+K23)) -> 11 | L24: =IF(L20-(L21+L22+L23)>11,11,L20-(L21+L22+L23)) -> 11 | ... P24: =IF(P20-(P21+P22+P23)>11,11,P20-(P21+P22+P23)) -> 3.4611
A25: 7. Свободный сток в реке(холостыесбросы) Qхол.сбр. | D25: м3/с | E25: =E20-(E21+E24) -> 0.6352 | F25: =F20-(F21+F24) -> 0.5952 | G25: =G20-(G21+G24) -> 0.9299 | H25: =H20-(H21+H24) -> 1.1271 | I25: =I20-(I21+I24) -> 2.465 | J25: =J20-(J21+J24) -> 4.148 | K25: =K20-(K21+K24) -> 7.77 | L25: =L20-(L21+L24) -> 7.67 | ... P25: =P20-(P21+P24) -> 0.7089
A26: 8. Статический напор, Нгеод=862.5-797,5=65м | D26: м | E26: 65 | F26: 65 | G26: 65 | H26: 65 | I26: 65 | J26: 65 | K26: 65 | L26: 65 | M26: 65 | N26: 65 | O26: 65 | P26: 65 | Q26: 65
A27: 9. Расчёт гидропотерь в деривационном тракте:
A28: 9.1. Потери в ГВУ, подводящем канале и отстойнике hгву | D28: м | E28: 0.5 | F28: 0.5 | G28: 0.5 | H28: 0.5 | I28: 0.5 | J28: 0.5 | K28: 0.5 | L28: 0.5 | M28: 0.5 | N28: 0.5 | O28: 0.5 | P28: 0.5
A29: 9.2. Деривационный ВОДОВОД
A30: 9.2.1. Протяжённость деривац.ВОДОВОДА Lд.в. | D30: м | E30: 4450 | F30: 4450 | G30: 4450 | H30: 4450 | I30: 4450 | J30: 4450 | K30: 4450 | L30: 4450 | M30: 4450 | N30: 4450 | O30: 4450 | P30: 4450 | Q30: 4450
A31: 9.2.2. Диаметр водовода D=2,1м | D31: м | E31: 2.1 | F31: 2.1 | G31: 2.1 | H31: 2.1 | I31: 2.1 | J31: 2.1 | K31: 2.1 | L31: 2.1 | M31: 2.1 | N31: 2.1 | O31: 2.1 | P31: 2.1
A32: 9.2.3. Абсолютная эквивал.шероховатость, kэ | D32: мм | E32: 0.5 | F32: 0.5 | G32: 0.5 | H32: 0.5 | I32: 0.5 | J32: 0.5 | K32: 0.5 | L32: 0.5 | M32: 0.5 | N32: 0.5 | O32: 0.5 | P32: 0.5
A33: 9.2.4. К-т потерь по длине λ=0,11х ( k/ D)0,25 | D33: ₋ | E33: =0.11*(E32/(1000*E31))^0.25 -> 0.013664079 | F33: =0.11*(F32/(1000*F31))^0.25 -> 0.013664079 | G33: =0.11*(G32/(1000*G31))^0.25 -> 0.013664079 | H33: =0.11*(H32/(1000*H31))^0.25 -> 0.013664079 | I33: =0.11*(I32/(1000*I31))^0.25 -> 0.013664079 | J33: =0.11*(J32/(1000*J31))^0.25 -> 0.013664079 | K33: =0.11*(K32/(1000*K31))^0.25 -> 0.013664079 | L33: =0.11*(L32/(1000*L31))^0.25 -> 0.013664079 | ... P33: =0.11*(P32/(1000*P31))^0.25 -> 0.013664079
A34: 9.2.5. λ x L/D | D34: ₋ | E34: =E33*E30/E31 -> 28.954834 | F34: =F33*F30/F31 -> 28.954834 | G34: =G33*G30/G31 -> 28.954834 | H34: =H33*H30/H31 -> 28.954834 | I34: =I33*I30/I31 -> 28.954834 | J34: =J33*J30/J31 -> 28.954834 | K34: =K33*K30/K31 -> 28.954834 | L34: =L33*L30/L31 -> 28.954834 | ... P34: =P33*P30/P31 -> 28.954834
A35: 9.2.6. ω=π x D2/4 - площадь водовода в свету | D35: м2 | E35: =3.1416*(E31)^2/4 -> 3.463614 | F35: =3.1416*(F31)^2/4 -> 3.463614 | G35: =3.1416*(G31)^2/4 -> 3.463614 | H35: =3.1416*(H31)^2/4 -> 3.463614 | I35: =3.1416*(I31)^2/4 -> 3.463614 | J35: =3.1416*(J31)^2/4 -> 3.463614 | K35: =3.1416*(K31)^2/4 -> 3.463614 | L35: =3.1416*(L31)^2/4 -> 3.463614 | ... P35: =3.1416*(P31)^2/4 -> 3.463614
A36: 9.2.7. V = Q/ω - скорость воды в деривации | D36: м/с | E36: =E24/E35 -> 0.96280937 | F36: =F24/F35 -> 0.90217905 | G36: =G24/G35 -> 1.3107985 | H36: =H24/H35 -> 0.78036987 | I36: =I24/I35 -> 1.8492245 | J36: =J24/J35 -> 2.2525605 | K36: =K24/K35 -> 3.1758735 | L36: =L24/L35 -> 3.1758735 | ... P36: =P24/P35 -> 0.99927417
A37: 9.2.8. V2 / 2g - скоростной напор | D37: м | E37: =(E36)^2/(2*9.81) -> 0.047247802 | F37: =(F36)^2/(2*9.81) -> 0.041484559 | G37: =(G36)^2/(2*9.81) -> 0.087573531 | H37: =(H36)^2/(2*9.81) -> 0.03103859 | I37: =(I36)^2/(2*9.81) -> 0.17429314 | J37: =(J36)^2/(2*9.81) -> 0.25861512 | K37: =(K36)^2/(2*9.81) -> 0.51407608 | L37: =(L36)^2/(2*9.81) -> 0.51407608 | ... P37: =(P36)^2/(2*9.81) -> 0.050894438
A38: 9.2.9. Гидропотери по длине водовода: hwl = λ x L / DxV2/2g | D38: м | E38: =E34*E37 -> 1.3680523 | F38: =F34*F37 -> 1.2011785 | G38: =G34*G37 -> 2.5356771 | H38: =H34*H37 -> 0.89871721 | I38: =I34*I37 -> 5.0466289 | J38: =J34*J37 -> 7.4881579 | K38: =K34*K37 -> 14.884987 | L38: =L34*L37 -> 14.884987 | ... P38: =P34*P37 -> 1.47364
A39: 9.2.10. Местные гидропотери в дер.водоводе: hм= 0,1хhwl | D39: м | E39: =0.1*E38 -> 0.13680523 | F39: =0.1*F38 -> 0.12011785 | G39: =0.1*G38 -> 0.25356771 | H39: =0.1*H38 -> 0.089871721 | I39: =0.1*I38 -> 0.50466289 | J39: =0.1*J38 -> 0.74881579 | K39: =0.1*K38 -> 1.4884987 | L39: =0.1*L38 -> 1.4884987 | ... P39: =0.1*P38 -> 0.147364
A40: 9.2.11.Суммарные потери в дер.водоводе: Нд.в.= hwl +hм | D40: м | E40: =E38+E39 -> 1.5048575 | F40: =F38+F39 -> 1.3212964 | G40: =G38+G39 -> 2.7892448 | H40: =H38+H39 -> 0.98858893 | I40: =I38+I39 -> 5.5512918 | J40: =J38+J39 -> 8.2369737 | K40: =K38+K39 -> 16.373486 | L40: =L38+L39 -> 16.373486 | ... P40: =P38+P39 -> 1.621004
A41: Полные гидропотери в тракте Hполн=hгву+Нд.в. | D41: м | E41: =E28+E40 -> 2.0048575 | F41: =F28+F40 -> 1.8212964 | G41: =G28+G40 -> 3.2892448 | H41: =H28+H40 -> 1.4885889 | I41: =I28+I40 -> 6.0512918 | J41: =J28+J40 -> 8.7369737 | K41: =K28+K40 -> 16.873486 | L41: =L28+L40 -> 16.873486 | ... P41: =P28+P40 -> 2.121004
A42: 5. Рабочий напор на ГЭС, Нгэс | D42: м | E42: =E26-E41 -> 62.995143 | F42: =F26-F41 -> 63.178704 | G42: =G26-G41 -> 61.710755 | H42: =H26-H41 -> 63.511411 | I42: =I26-I41 -> 58.948708 | J42: =J26-J41 -> 56.263026 | K42: =K26-K41 -> 48.126514 | L42: =L26-L41 -> 48.126514 | ... P42: =P26-P41 -> 62.878996
A43: 6. К.П.Д. турбины ηт | D43: % | E43: 93 | F43: 93 | G43: 93 | H43: 92.5 | I43: 92.5 | J43: 92.5 | K43: 92.5 | L43: 92.5 | M43: 92.5 | N43: 92.7 | O43: 91 | P43: 92.5
A44: 7. К.П.Д. генератора ηг | D44: % | E44: 97.2 | F44: 97.2 | G44: 97.2 | H44: 97.2 | I44: 97.2 | J44: 97.2 | K44: 97.2 | L44: 97.2 | M44: 97.2 | N44: 97.2 | O44: 97.2 | P44: 97.2
...

Sheet Произв.затраты
A1: =Panel!A1
A2: =Panel!A2 -> Строительство ГЭС -5 МВТ
A4: ПРОИЗВОДСТВЕННЫЕ ИЗДЕРЖКИ
A6: в тыс.тенге, если не указано иное
A7: № | B7: Элементы затрат | C7: янв | D7: фев | E7: мар | F7: апр | G7: май | H7: июн | I7: июл | J7: авг | K7: сен | L7: окт | M7: ноя | N7: дек | O7: 2026 | P7: янв | Q7: фев | R7: мар | S7: апр | T7: май | U7: июн | V7: июл | W7: авг | X7: сен | Y7: окт | Z7: ноя | AA7: дек | AB7: 2027 | AC7: янв | AD7: фев | AE7: мар | AF7: апр | AG7: май | AH7: июн | AI7: июл | AJ7: авг | AK7: сен | AL7: окт | AM7: ноя | AN7: дек | AO7: 2028 | AP7: 2029 | AQ7: 2030 | AR7: 2031 | AS7: 2032 | AT7: 2033 | AU7: 2034 | AV7: 2035 | AW7: 2036 | AX7: 2037 | AY7: 2038 | AZ7: 2039 | BA7: 2040 | BB7: 2041 | BC7: 2042
A8: 1.1 | B8: =B24 -> Амортизационные отчисления | C8: =C24 -> 14417.246 | D8: =D24 -> 14417.246 | E8: =E24 -> 14417.246 | F8: =F24 -> 14417.246 | G8: =G24 -> 14417.246 | H8: =H24 -> 14417.246 | I8: =I24 -> 14417.246 | ... BC8: =BC24 -> 173006.95
A9: 1.2 | B9: ='Произв.затраты'!B41 -> Текущий ремонт оборудования | C9: ='Произв.затраты'!C42 -> 194.05348 | D9: ='Произв.затраты'!D42 -> 194.05348 | E9: ='Произв.затраты'!E42 -> 194.05348 | F9: ='Произв.затраты'!F42 -> 194.05348 | G9: ='Произв.затраты'!G42 -> 194.05348 | H9: ='Произв.затраты'!H42 -> 194.05348 | I9: ='Произв.затраты'!I42 -> 194.05348 | J9: ='Произв.затраты'!J42 -> 194.05348 | ... BC9: ='Произв.затраты'!BC42 -> 13675.822
A10: 1.3 | B10: ='Произв.затраты'!B51 -> Электроэнергия на объекте | C10: ='Произв.затраты'!C52 -> 99.055116 | D10: ='Произв.затраты'!D52 -> 99.055116 | E10: ='Произв.затраты'!E52 -> 99.055116 | F10: ='Произв.затраты'!F52 -> 99.055116 | G10: ='Произв.затраты'!G52 -> 99.055116 | H10: ='Произв.затраты'!H52 -> 99.055116 | I10: ='Произв.затраты'!I52 -> 99.055116 | J10: ='Произв.затраты'!J52 -> 99.055116 | ... BC10: ='Произв.затраты'!BC52 -> 6980.86
A11: 1.4 | B11: ='Произв.затраты'!B59 -> Налог на имущество | C11: ='Произв.затраты'!C60 -> 1008.2866 | D11: ='Произв.затраты'!D60 -> 1008.2866 | E11: ='Произв.затраты'!E60 -> 1008.2866 | F11: ='Произв.затраты'!F60 -> 1008.2866 | G11: ='Произв.затраты'!G60 -> 1008.2866 | H11: ='Произв.затраты'!H60 -> 1008.2866 | I11: ='Произв.затраты'!I60 -> 1008.2866 | J11: ='Произв.затраты'!J60 -> 1008.2866 | ... BC11: ='Произв.затраты'!BC60 -> 0
A12: 1.5 | B12: ='Произв.затраты'!B71 -> Земельный налог | C12: ='Произв.затраты'!C72 -> 8.6245833 | D12: ='Произв.затраты'!D72 -> 8.6245833 | E12: ='Произв.затраты'!E72 -> 8.6245833 | F12: ='Произв.затраты'!F72 -> 8.6245833 | G12: ='Произв.затраты'!G72 -> 8.6245833 | H12: ='Произв.затраты'!H72 -> 8.6245833 | I12: ='Произв.затраты'!I72 -> 8.6245833 | J12: ='Произв.затраты'!J72 -> 8.6245833 | ... BC12: ='Произв.затраты'!BC72 -> 103.495
A13: 1.6 | B13: ='Произв.затраты'!B81 -> Плата за пользование водными ресурсами | C13: ='Произв.затраты'!C82 -> 101.31772 | D13: ='Произв.затраты'!D82 -> 85.999872 | E13: ='Произв.затраты'!E82 -> 135.12472 | F13: ='Произв.затраты'!F82 -> 79.690879 | G13: ='Произв.затраты'!G82 -> 181.11764 | H13: ='Произв.затраты'!H82 -> 203.77735 | I13: ='Произв.затраты'!I82 -> 253.94777 | J13: ='Произв.затраты'!J82 -> 253.94777 | ... BC13: ='Произв.затраты'!BC82 -> 1915.9618
A14: 1.7 | B14: ='Произв.затраты'!B91 -> Услуги диспетчеризации | C14: ='Произв.затраты'!C92 -> 403.80267 | D14: ='Произв.затраты'!D92 -> 382.8554 | E14: ='Произв.затраты'!E92 -> 601.55007 | F14: ='Произв.затраты'!F92 -> 354.76893 | G14: ='Произв.затраты'!G92 -> 806.30195 | H14: ='Произв.затраты'!H92 -> 907.17877 | I14: ='Произв.затраты'!I92 -> 1130.5281 | J14: ='Произв.затраты'!J92 -> 1130.5281 | ... BC14: ='Произв.затраты'!BC92 -> 49815.254
A15: 1.8 | B15: ='Произв.затраты'!B101 -> Оперативно-техническое и диспетчерское обслуживание | C15: ='Произв.затраты'!C102 -> 2151.1879 | D15: ='Произв.затраты'!D102 -> 2151.1879 | E15: ='Произв.затраты'!E102 -> 2151.1879 | F15: ='Произв.затраты'!F102 -> 2151.1879 | G15: ='Произв.затраты'!G102 -> 2151.1879 | H15: ='Произв.затраты'!H102 -> 2151.1879 | I15: ='Произв.затраты'!I102 -> 2151.1879 | J15: ='Произв.затраты'!J102 -> 2151.1879 | ... BC15: ='Произв.затраты'!BC102 -> 151603.9
A16: 1.9 | B16: Непредвиденные расходы | C16: ='Произв.затраты'!C113 -> 145.0465 | D16: ='Произв.затраты'!D113 -> 123.11746 | E16: ='Произв.затраты'!E113 -> 193.44463 | F16: ='Произв.затраты'!F113 -> 114.08551 | G16: ='Произв.затраты'!G113 -> 259.28811 | H16: ='Произв.затраты'!H113 -> 291.72777 | I16: ='Произв.затраты'!I113 -> 363.55177 | J16: ='Произв.затраты'!J113 -> 363.55177 | ... BC16: ='Произв.затраты'!BC113 -> 12421.436
B17: Итого | C17: =SUM(C8:C16) -> 18528.62 | D17: =SUM(D8:D16) -> 18470.426 | E17: =SUM(E8:E16) -> 18808.573 | F17: =SUM(F8:F16) -> 18426.999 | G17: =SUM(G8:G16) -> 19125.161 | H17: =SUM(H8:H16) -> 19281.138 | I17: =SUM(I8:I16) -> 19626.481 | J17: =SUM(J8:J16) -> 19626.481 | ... BC17: =SUM(BC8:BC16) -> 409523.68
A20: РАСЧЕТ АМОРТИЗАЦИОННЫХ ОТЧИСЛЕНИЙ НА ПРОИЗВОДСТВЕННЫЕ ОСНОВНЫЕ СРЕДСТВА
A22: в тыс. тенге, если не указано иное
A23: № | B23: Наименование | C23: янв | D23: фев | E23: мар | F23: апр | G23: май | H23: июн | I23: июл | J23: авг | K23: сен | L23: окт | M23: ноя | N23: дек | O23: 2026 | P23: янв | Q23: фев | R23: мар | S23: апр | T23: май | U23: июн | V23: июл | W23: авг | X23: сен | Y23: окт | Z23: ноя | AA23: дек | AB23: 2027 | AC23: янв | AD23: фев | AE23: мар | AF23: апр | AG23: май | AH23: июн | AI23: июл | AJ23: авг | AK23: сен | AL23: окт | AM23: ноя | AN23: дек | AO23: 2028 | AP23: 2029 | AQ23: 2030 | AR23: 2031 | AS23: 2032 | AT23: 2033 | AU23: 2034 | AV23: 2035 | AW23: 2036 | AX23: 2037 | AY23: 2038 | AZ23: 2039 | BA23: 2040 | BB23: 2041 | BC23: 2042
A24: 1 | B24: Амортизационные отчисления | C24: =F32 -> 14417.246 | D24: =C24 -> 14417.246 | E24: =D24 -> 14417.246 | F24: =E24 -> 14417.246 | G24: =F24 -> 14417.246 | H24: =G24 -> 14417.246 | I24: =H24 -> 14417.246 | J24: =I24 -> 14417.246 | K24: =J24 -> 14417.246 | ... N24: =M24 -> 14417.246 | O24: =SUM(C24:N24) -> 173006.95 | P24: =C24 -> 14417.246 | Q24: =D24 -> 14417.246 | R24: =E24 -> 14417.246 | S24: =F24 -> 14417.246 | T24: =G24 -> 14417.246 | U24: =H24 -> 14417.246 | V24: =I24 -> 14417.246 | W24: =J24 -> 14417.246 | ... AA24: =N24 -> 14417.246 | AB24: =SUM(P24:AA24) -> 173006.95 | AC24: =P24 -> 14417.246 | AD24: =AC24 -> 14417.246 | AE24: =AD24 -> 14417.246 | AF24: =AE24 -> 14417.246 | AG24: =AF24 -> 14417.246 | AH24: =AG24 -> 14417.246 | AI24: =AH24 -> 14417.246 | AJ24: =AI24 -> 14417.246 | AK24: =AJ24 -> 14417.246 | ... AN24: =AM24 -> 14417.246 | AO24: =SUM(AC24:AN24) -> 173006.95 | AP24: =AO24 -> 173006.95 | AQ24: =AP24 -> 173006.95 | AR24: =AQ24 -> 173006.95 | AS24: =AR24 -> 173006.95 | AT24: =AS24 -> 173006.95 | AU24: =AT24 -> 173006.95 | AV24: =AU24 -> 173006.95 | AW24: =AV24 -> 173006.95 | ... BC24: =BB24 -> 173006.95
B25: Итого | C25: =SUM(C24) -> 14417.246 | D25: =SUM(D24) -> 14417.246 | E25: =SUM(E24) -> 14417.246 | F25: =SUM(F24) -> 14417.246 | G25: =SUM(G24) -> 14417.246 | H25: =SUM(H24) -> 14417.246 | I25: =SUM(I24) -> 14417.246 | J25: =SUM(J24) -> 14417.246 | ... BC25: =SUM(BC24) -> 173006.95
A28: в тыс. тенге, если не указано иное
A29: № | B29: Наименование | C29: Стоимость без учета НДС | D29: Срок службы, лет | E29: Ставка, % | F29: Амортизационные отчисления
F30: в мес. | G30: в год
A31: 1.1 | B31: ГЭС-1 | C31: =('Инвестиции'!C14+'Инвестиции'!C13+'Инвестиции'!C12+'Инвестиции'!C11+'Инвестиции'!C9+'Инвестиции'!C10)/(1+Panel!B26) -> 2595104.3 | D31: =Panel!B22 -> 15 | E31: =1/D31 -> 0.066666667 | F31: =C31*E31/12 -> 14417.246 | G31: =F31*12 -> 173006.95
B32: Итого | C32: =SUM(C31) -> 2595104.3 | F32: =SUM(F31) -> 14417.246 | G32: =SUM(G31) -> 173006.95
A35: Текущий ремонт оборудования
B37: Норматив затрат | C37: =2084728.53/12 -> 173727.38 | D37: тенге/мес. | E37: Норматив на основе эксплуатации
A39: в тыс. тенге, если не указано иное
A40: № | B40: Наименование | C40: янв | D40: фев | E40: мар | F40: апр | G40: май | H40: июн | I40: июл | J40: авг | K40: сен | L40: окт | M40: ноя | N40: дек | O40: 2026 | P40: янв | Q40: фев | R40: мар | S40: апр | T40: май | U40: июн | V40: июл | W40: авг | X40: сен | Y40: окт | Z40: ноя | AA40: дек | AB40: 2027 | AC40: янв | AD40: фев | AE40: мар | AF40: апр | AG40: май | AH40: июн | AI40: июл | AJ40: авг | AK40: сен | AL40: окт | AM40: ноя | AN40: дек | AO40: 2028 | AP40: 2029 | AQ40: 2030 | AR40: 2031 | AS40: 2032 | AT40: 2033 | AU40: 2034 | AV40: 2035 | AW40: 2036 | AX40: 2037 | AY40: 2038 | AZ40: 2039 | BA40: 2040 | BB40: 2041 | BC40: 2042
A41: 1 | B41: Текущий ремонт оборудования | C41: =C37*(1+Panel!$B$43)/1000 -> 194.05348 | D41: =C41 -> 194.05348 | E41: =D41 -> 194.05348 | F41: =E41 -> 194.05348 | G41: =F41 -> 194.05348 | H41: =G41 -> 194.05348 | I41: =H41 -> 194.05348 | J41: =I41 -> 194.05348 | K41: =J41 -> 194.05348 | ... N41: =M41 -> 194.05348 | O41: =SUM(C41:N41) -> 2328.6418 | P41: =N41*(1+Panel!$B$43) -> 216.75774 | Q41: =P41 -> 216.75774 | R41: =Q41 -> 216.75774 | S41: =R41 -> 216.75774 | T41: =S41 -> 216.75774 | U41: =T41 -> 216.75774 | V41: =U41 -> 216.75774 | W41: =V41 -> 216.75774 | X41: =W41 -> 216.75774 | ... AA41: =Z41 -> 216.75774 | AB41: =SUM(P41:AA41) -> 2601.0929 | AC41: =AA41*(1+Panel!$B$43) -> 242.11839 | AD41: =AC41 -> 242.11839 | AE41: =AD41 -> 242.11839 | AF41: =AE41 -> 242.11839 | AG41: =AF41 -> 242.11839 | AH41: =AG41 -> 242.11839 | AI41: =AH41 -> 242.11839 | AJ41: =AI41 -> 242.11839 | AK41: =AJ41 -> 242.11839 | ... AN41: =AM41 -> 242.11839 | AO41: =SUM(AC41:AN41) -> 2905.4207 | AP41: =AO41*(1+Panel!$B$43) -> 3245.3549 | AQ41: =AP41*(1+Panel!$B$43) -> 3625.0615 | AR41: =AQ41*(1+Panel!$B$43) -> 4049.1937 | AS41: =AR41*(1+Panel!$B$43) -> 4522.9493 | AT41: =AS41*(1+Panel!$B$43) -> 5052.1344 | AU41: =AT41*(1+Panel!$B$43) -> 5643.2341 | AV41: =AU41*(1+Panel!$B$43) -> 6303.4925 | AW41: =AV41*(1+Panel!$B$43) -> 7041.0011 | ... BC41: =BB41*(1+Panel!$B$43) -> 13675.822
B42: Итого | C42: =SUM(C41) -> 194.05348 | D42: =SUM(D41) -> 194.05348 | E42: =SUM(E41) -> 194.05348 | F42: =SUM(F41) -> 194.05348 | G42: =SUM(G41) -> 194.05348 | H42: =SUM(H41) -> 194.05348 | I42: =SUM(I41) -> 194.05348 | J42: =SUM(J41) -> 194.05348 | ... BC42: =SUM(BC41) -> 13675.822
A45: Электроэнергия на объекте
B47: Норматив затрат | C47: =952690.45/12 -> 79390.871 | D47: тенге/мес. | E47: Норматив на основе эксплуатации
A49: в тыс. тенге, если не указано иное
A50: № | B50: Наименование | C50: янв | D50: фев | E50: мар | F50: апр | G50: май | H50: июн | I50: июл | J50: авг | K50: сен | L50: окт | M50: ноя | N50: дек | O50: 2026 | P50: янв | Q50: фев | R50: мар | S50: апр | T50: май | U50: июн | V50: июл | W50: авг | X50: сен | Y50: окт | Z50: ноя | AA50: дек | AB50: 2027 | AC50: янв | AD50: фев | AE50: мар | AF50: апр | AG50: май | AH50: июн | AI50: июл | AJ50: авг | AK50: сен | AL50: окт | AM50: ноя | AN50: дек | AO50: 2028 | AP50: 2029 | AQ50: 2030 | AR50: 2031 | AS50: 2032 | AT50: 2033 | AU50: 2034 | AV50: 2035 | AW50: 2036 | AX50: 2037 | AY50: 2038 | AZ50: 2039 | BA50: 2040 | BB50: 2041 | BC50: 2042
A51: 1 | B51: Электроэнергия на объекте | C51: =C47*(1+Panel!$B$43)*(1+Panel!$B$43)/1000 -> 99.055116 | D51: =C51 -> 99.055116 | E51: =D51 -> 99.055116 | F51: =E51 -> 99.055116 | G51: =F51 -> 99.055116 | H51: =G51 -> 99.055116 | I51: =H51 -> 99.055116 | J51: =I51 -> 99.055116 | K51: =J51 -> 99.055116 | ... N51: =M51 -> 99.055116 | O51: =SUM(C51:N51) -> 1188.6614 | P51: =N51*(1+Panel!$B$43) -> 110.64456 | Q51: =P51 -> 110.64456 | R51: =Q51 -> 110.64456 | S51: =R51 -> 110.64456 | T51: =S51 -> 110.64456 | U51: =T51 -> 110.64456 | V51: =U51 -> 110.64456 | W51: =V51 -> 110.64456 | X51: =W51 -> 110.64456 | ... AA51: =Z51 -> 110.64456 | AB51: =SUM(P51:AA51) -> 1327.7348 | AC51: =AA51*(1+Panel!$B$43) -> 123.58998 | AD51: =AC51 -> 123.58998 | AE51: =AD51 -> 123.58998 | AF51: =AE51 -> 123.58998 | AG51: =AF51 -> 123.58998 | AH51: =AG51 -> 123.58998 | AI51: =AH51 -> 123.58998 | AJ51: =AI51 -> 123.58998 | AK51: =AJ51 -> 123.58998 | ... AN51: =AM51 -> 123.58998 | AO51: =SUM(AC51:AN51) -> 1483.0797 | AP51: =AO51*(1+Panel!$B$43) -> 1656.6001 | AQ51: =AP51*(1+Panel!$B$43) -> 1850.4223 | AR51: =AQ51*(1+Panel!$B$43) -> 2066.9217 | AS51: =AR51*(1+Panel!$B$43) -> 2308.7515 | AT51: =AS51*(1+Panel!$B$43) -> 2578.8755 | AU51: =AT51*(1+Panel!$B$43) -> 2880.6039 | AV51: =AU51*(1+Panel!$B$43) -> 3217.6345 | AW51: =AV51*(1+Panel!$B$43) -> 3594.0978 | ... BC51: =BB51*(1+Panel!$B$43) -> 6980.86
B52: Итого | C52: =SUM(C51) -> 99.055116 | D52: =SUM(D51) -> 99.055116 | E52: =SUM(E51) -> 99.055116 | F52: =SUM(F51) -> 99.055116 | G52: =SUM(G51) -> 99.055116 | H52: =SUM(H51) -> 99.055116 | I52: =SUM(I51) -> 99.055116 | J52: =SUM(J51) -> 99.055116 | ... BC52: =SUM(BC51) -> 6980.86
A55: РАСЧЕТ НАЛОГА НА ИМУЩЕСТВО
A57: в тыс.тенге, если не указано иное
B58: Наименование | C58: янв | D58: фев | E58: мар | F58: апр | G58: май | H58: июн | I58: июл | J58: авг | K58: сен | L58: окт | M58: ноя | N58: дек | O58: 2026 | P58: янв | Q58: фев | R58: мар | S58: апр | T58: май | U58: июн | V58: июл | W58: авг | X58: сен | Y58: окт | Z58: ноя | AA58: дек | AB58: 2027 | AC58: янв | AD58: фев | AE58: мар | AF58: апр | AG58: май | AH58: июн | AI58: июл | AJ58: авг | AK58: сен | AL58: окт | AM58: ноя | AN58: дек | AO58: 2028 | AP58: 2029 | AQ58: 2030 | AR58: 2031 | AS58: 2032 | AT58: 2033 | AU58: 2034 | AV58: 2035 | AW58: 2036 | AX58: 2037 | AY58: 2038 | AZ58: 2039 | BA58: 2040 | BB58: 2041 | BC58: 2042
...

Sheet Адм.затраты
A1: =Panel!A1
A2: =Panel!A2 -> Строительство ГЭС -5 МВТ
A4: АДМИНИСТРАТИВНЫЕ ИЗДЕРЖКИ
A6: в тыс.тенге, если не указано иное
A7: № | B7: Элементы затрат | C7: янв | D7: фев | E7: мар | F7: апр | G7: май | H7: июн | I7: июл | J7: авг | K7: сен | L7: окт | M7: ноя | N7: дек | O7: 2026 | P7: янв | Q7: фев | R7: мар | S7: апр | T7: май | U7: июн | V7: июл | W7: авг | X7: сен | Y7: окт | Z7: ноя | AA7: дек | AB7: 2027 | AC7: янв | AD7: фев | AE7: мар | AF7: апр | AG7: май | AH7: июн | AI7: июл | AJ7: авг | AK7: сен | AL7: окт | AM7: ноя | AN7: дек | AO7: 2028 | AP7: 2029 | AQ7: 2030 | AR7: 2031 | AS7: 2032 | AT7: 2033 | AU7: 2034 | AV7: 2035 | AW7: 2036 | AX7: 2037 | AY7: 2038 | AZ7: 2039 | BA7: 2040 | BB7: 2041 | BC7: 2042
A8: 1.1 | B8: Гос.пошлина | C8: 1.3708333 | D8: 1.3708333 | E8: 1.3708333 | F8: 1.3708333 | G8: 1.3708333 | H8: 1.3708333 | I8: 1.3708333 | J8: 1.3708333 | K8: 1.3708333 | L8: 1.3708333 | M8: 1.3708333 | N8: 1.3708333 | O8: =SUM(C8:N8) -> 16.45 | P8: =O8/12 -> 1.3708333 | Q8: =P8 -> 1.3708333 | R8: =Q8 -> 1.3708333 | S8: =R8 -> 1.3708333 | T8: =S8 -> 1.3708333 | U8: =T8 -> 1.3708333 | V8: =U8 -> 1.3708333 | W8: =V8 -> 1.3708333 | X8: =W8 -> 1.3708333 | ... AA8: =Z8 -> 1.3708333 | AB8: =SUM(P8:AA8) -> 16.45 | AC8: =AB8/12 -> 1.3708333 | AD8: =AC8 -> 1.3708333 | AE8: =AD8 -> 1.3708333 | AF8: =AE8 -> 1.3708333 | AG8: =AF8 -> 1.3708333 | AH8: =AG8 -> 1.3708333 | AI8: =AH8 -> 1.3708333 | AJ8: =AI8 -> 1.3708333 | AK8: =AJ8 -> 1.3708333 | ... AN8: =AM8 -> 1.3708333 | AO8: =SUM(AC8:AN8) -> 16.45 | AP8: =AO8 -> 16.45 | AQ8: =AP8 -> 16.45 | AR8: =AQ8 -> 16.45 | AS8: =AR8 -> 16.45 | AT8: =AS8 -> 16.45 | AU8: =AT8 -> 16.45 | AV8: =AU8 -> 16.45 | AW8: =AV8 -> 16.45 | ... BC8: =BB8 -> 16.45
A9: 1.2 | B9: Гос.регистрация | C9: 2.1744167 | D9: 2.1744167 | E9: 2.1744167 | F9: 2.1744167 | G9: 2.1744167 | H9: 2.1744167 | I9: 2.1744167 | J9: 2.1744167 | K9: 2.1744167 | L9: 2.1744167 | M9: 2.1744167 | N9: 2.1744167 | O9: =SUM(C9:N9) -> 26.093 | P9: =O9/12 -> 2.1744167 | Q9: =P9 -> 2.1744167 | R9: =Q9 -> 2.1744167 | S9: =R9 -> 2.1744167 | T9: =S9 -> 2.1744167 | U9: =T9 -> 2.1744167 | V9: =U9 -> 2.1744167 | W9: =V9 -> 2.1744167 | X9: =W9 -> 2.1744167 | ... AA9: =Z9 -> 2.1744167 | AB9: =SUM(P9:AA9) -> 26.093 | AC9: =AB9/12 -> 2.1744167 | AD9: =AC9 -> 2.1744167 | AE9: =AD9 -> 2.1744167 | AF9: =AE9 -> 2.1744167 | AG9: =AF9 -> 2.1744167 | AH9: =AG9 -> 2.1744167 | AI9: =AH9 -> 2.1744167 | AJ9: =AI9 -> 2.1744167 | AK9: =AJ9 -> 2.1744167 | ... AN9: =AM9 -> 2.1744167 | AO9: =SUM(AC9:AN9) -> 26.093 | AP9: =AO9 -> 26.093 | AQ9: =AP9 -> 26.093 | AR9: =AQ9 -> 26.093 | AS9: =AR9 -> 26.093 | AT9: =AS9 -> 26.093 | AU9: =AT9 -> 26.093 | AV9: =AU9 -> 26.093 | AW9: =AV9 -> 26.093 | ... BC9: =BB9 -> 26.093
A10: 1.3 | B10: Заправка картриджа | C10: 1.6666667 | D10: 1.6666667 | E10: 1.6666667 | F10: 1.6666667 | G10: 1.6666667 | H10: 1.6666667 | I10: 1.6666667 | J10: 1.6666667 | K10: 1.6666667 | L10: 1.6666667 | M10: 1.6666667 | N10: 1.6666667 | O10: =SUM(C10:N10) -> 20 | P10: =(O10/12)*(1+Panel!$B$43) -> 1.8616667 | Q10: =P10 -> 1.8616667 | R10: =Q10 -> 1.8616667 | S10: =R10 -> 1.8616667 | T10: =S10 -> 1.8616667 | U10: =T10 -> 1.8616667 | V10: =U10 -> 1.8616667 | W10: =V10 -> 1.8616667 | X10: =W10 -> 1.8616667 | ... AA10: =Z10 -> 1.8616667 | AB10: =SUM(P10:AA10) -> 22.34 | AC10: =(AB10/12)*(1+Panel!$B$43) -> 2.0794817 | AD10: =AC10 -> 2.0794817 | AE10: =AD10 -> 2.0794817 | AF10: =AE10 -> 2.0794817 | AG10: =AF10 -> 2.0794817 | AH10: =AG10 -> 2.0794817 | AI10: =AH10 -> 2.0794817 | AJ10: =AI10 -> 2.0794817 | AK10: =AJ10 -> 2.0794817 | ... AN10: =AM10 -> 2.0794817 | AO10: =SUM(AC10:AN10) -> 24.95378 | AP10: =(AO10)*(1+Panel!$B$43) -> 27.873372 | AQ10: =(AP10)*(1+Panel!$B$43) -> 31.134557 | AR10: =(AQ10)*(1+Panel!$B$43) -> 34.7773 | AS10: =(AR10)*(1+Panel!$B$43) -> 38.846244 | AT10: =(AS10)*(1+Panel!$B$43) -> 43.391255 | AU10: =(AT10)*(1+Panel!$B$43) -> 48.468031 | AV10: =(AU10)*(1+Panel!$B$43) -> 54.138791 | AW10: =(AV10)*(1+Panel!$B$43) -> 60.47303 | ... BC10: =(BB10)*(1+Panel!$B$43) -> 117.4575
A11: 1.4 | B11: Изготовление и цветная распечатка | C11: 0.27833333 | D11: 0.27833333 | E11: 0.27833333 | F11: 0.27833333 | G11: 0.27833333 | H11: 0.27833333 | I11: 0.27833333 | J11: 0.27833333 | K11: 0.27833333 | L11: 0.27833333 | M11: 0.27833333 | N11: 0.27833333 | O11: =SUM(C11:N11) -> 3.34 | P11: =(O11/12)*(1+Panel!$B$43) -> 0.31089833 | Q11: =P11 -> 0.31089833 | R11: =Q11 -> 0.31089833 | S11: =R11 -> 0.31089833 | T11: =S11 -> 0.31089833 | U11: =T11 -> 0.31089833 | V11: =U11 -> 0.31089833 | W11: =V11 -> 0.31089833 | X11: =W11 -> 0.31089833 | ... AA11: =Z11 -> 0.31089833 | AB11: =SUM(P11:AA11) -> 3.73078 | AC11: =(AB11/12)*(1+Panel!$B$43) -> 0.34727344 | AD11: =AC11 -> 0.34727344 | AE11: =AD11 -> 0.34727344 | AF11: =AE11 -> 0.34727344 | AG11: =AF11 -> 0.34727344 | AH11: =AG11 -> 0.34727344 | AI11: =AH11 -> 0.34727344 | AJ11: =AI11 -> 0.34727344 | AK11: =AJ11 -> 0.34727344 | ... AN11: =AM11 -> 0.34727344 | AO11: =SUM(AC11:AN11) -> 4.1672813 | AP11: =(AO11)*(1+Panel!$B$43) -> 4.6548532 | AQ11: =(AP11)*(1+Panel!$B$43) -> 5.199471 | AR11: =(AQ11)*(1+Panel!$B$43) -> 5.8078091 | AS11: =(AR11)*(1+Panel!$B$43) -> 6.4873228 | AT11: =(AS11)*(1+Panel!$B$43) -> 7.2463395 | AU11: =(AT11)*(1+Panel!$B$43) -> 8.0941612 | AV11: =(AU11)*(1+Panel!$B$43) -> 9.0411781 | AW11: =(AV11)*(1+Panel!$B$43) -> 10.098996 | ... BC11: =(BB11)*(1+Panel!$B$43) -> 19.615403
A12: 1.5 | B12: Канцелярские товары | C12: 5.1040408 | D12: 5.1040408 | E12: 5.1040408 | F12: 5.1040408 | G12: 5.1040408 | H12: 5.1040408 | I12: 5.1040408 | J12: 5.1040408 | K12: 5.1040408 | L12: 5.1040408 | M12: 5.1040408 | N12: 5.1040408 | O12: =SUM(C12:N12) -> 61.24849 | P12: =(O12/12)*(1+Panel!$B$43) -> 5.7012136 | Q12: =P12 -> 5.7012136 | R12: =Q12 -> 5.7012136 | S12: =R12 -> 5.7012136 | T12: =S12 -> 5.7012136 | U12: =T12 -> 5.7012136 | V12: =U12 -> 5.7012136 | W12: =V12 -> 5.7012136 | X12: =W12 -> 5.7012136 | ... AA12: =Z12 -> 5.7012136 | AB12: =SUM(P12:AA12) -> 68.414563 | AC12: =(AB12/12)*(1+Panel!$B$43) -> 6.3682556 | AD12: =AC12 -> 6.3682556 | AE12: =AD12 -> 6.3682556 | AF12: =AE12 -> 6.3682556 | AG12: =AF12 -> 6.3682556 | AH12: =AG12 -> 6.3682556 | AI12: =AH12 -> 6.3682556 | AJ12: =AI12 -> 6.3682556 | AK12: =AJ12 -> 6.3682556 | ... AN12: =AM12 -> 6.3682556 | AO12: =SUM(AC12:AN12) -> 76.419067 | AP12: =(AO12)*(1+Panel!$B$43) -> 85.360098 | AQ12: =(AP12)*(1+Panel!$B$43) -> 95.34723 | AR12: =(AQ12)*(1+Panel!$B$43) -> 106.50286 | AS12: =(AR12)*(1+Panel!$B$43) -> 118.96369 | AT12: =(AS12)*(1+Panel!$B$43) -> 132.88244 | AU12: =(AT12)*(1+Panel!$B$43) -> 148.42969 | AV12: =(AU12)*(1+Panel!$B$43) -> 165.79596 | AW12: =(AV12)*(1+Panel!$B$43) -> 185.19409 | ... BC12: =(BB12)*(1+Panel!$B$43) -> 359.70474
A13: 1.6 | B13: Налог на транспорт | C13: 0.52 | D13: 0.52 | E13: 0.52 | F13: 0.52 | G13: 0.52 | H13: 0.52 | I13: 0.52 | J13: 0.52 | K13: 0.52 | L13: 0.52 | M13: 0.52 | N13: 0.52 | O13: =SUM(C13:N13) -> 6.24 | P13: =O13/12 -> 0.52 | Q13: =P13 -> 0.52 | R13: =Q13 -> 0.52 | S13: =R13 -> 0.52 | T13: =S13 -> 0.52 | U13: =T13 -> 0.52 | V13: =U13 -> 0.52 | W13: =V13 -> 0.52 | X13: =W13 -> 0.52 | ... AA13: =Z13 -> 0.52 | AB13: =SUM(P13:AA13) -> 6.24 | AC13: =AB13/12 -> 0.52 | AD13: =AC13 -> 0.52 | AE13: =AD13 -> 0.52 | AF13: =AE13 -> 0.52 | AG13: =AF13 -> 0.52 | AH13: =AG13 -> 0.52 | AI13: =AH13 -> 0.52 | AJ13: =AI13 -> 0.52 | AK13: =AJ13 -> 0.52 | ... AN13: =AM13 -> 0.52 | AO13: =SUM(AC13:AN13) -> 6.24 | AP13: =AO13 -> 6.24 | AQ13: =AP13 -> 6.24 | AR13: =AQ13 -> 6.24 | AS13: =AR13 -> 6.24 | AT13: =AS13 -> 6.24 | AU13: =AT13 -> 6.24 | AV13: =AU13 -> 6.24 | AW13: =AV13 -> 6.24 | ... BC13: =BB13 -> 6.24
A14: 1.7 | B14: Отчисления ОСМС | C14: 11.111111 | D14: 11.111111 | E14: 11.111111 | F14: 11.111111 | G14: 11.111111 | H14: 11.111111 | I14: 11.111111 | J14: 11.111111 | K14: 11.111111 | L14: 11.111111 | M14: 11.111111 | N14: 11.111111 | O14: =SUM(C14:N14) -> 133.33333 | P14: =O14/12 -> 11.111111 | Q14: =P14 -> 11.111111 | R14: =Q14 -> 11.111111 | S14: =R14 -> 11.111111 | T14: =S14 -> 11.111111 | U14: =T14 -> 11.111111 | V14: =U14 -> 11.111111 | W14: =V14 -> 11.111111 | X14: =W14 -> 11.111111 | ... AA14: =Z14 -> 11.111111 | AB14: =SUM(P14:AA14) -> 133.33333 | AC14: =P48/1000 -> 22.222222 | AD14: =AC14 -> 22.222222 | AE14: =AD14 -> 22.222222 | AF14: =AE14 -> 22.222222 | AG14: =AF14 -> 22.222222 | AH14: =AG14 -> 22.222222 | AI14: =AH14 -> 22.222222 | AJ14: =AI14 -> 22.222222 | AK14: =AJ14 -> 22.222222 | ... AN14: =AM14 -> 22.222222 | AO14: =SUM(AC14:AN14) -> 266.66667 | AP14: =AO14 -> 266.66667 | AQ14: =AP14 -> 266.66667 | AR14: =AQ14 -> 266.66667 | AS14: =AR14 -> 266.66667 | AT14: =AS14 -> 266.66667 | AU14: =AT14 -> 266.66667 | AV14: =AU14 -> 266.66667 | AW14: =AV14 -> 266.66667 | ... BC14: =BB14 -> 266.66667
A15: 1.8 | B15: Оценка имущества | C15: 41.666667 | D15: 41.666667 | E15: 41.666667 | F15: 41.666667 | G15: 41.666667 | H15: 41.666667 | I15: 41.666667 | J15: 41.666667 | K15: 41.666667 | L15: 41.666667 | M15: 41.666667 | N15: 41.666667 | O15: =SUM(C15:N15) -> 500 | P15: =O15/12 -> 41.666667 | Q15: =P15 -> 41.666667 | R15: =Q15 -> 41.666667 | S15: =R15 -> 41.666667 | T15: =S15 -> 41.666667 | U15: =T15 -> 41.666667 | V15: =U15 -> 41.666667 | W15: =V15 -> 41.666667 | X15: =W15 -> 41.666667 | ... AA15: =Z15 -> 41.666667 | AB15: =SUM(P15:AA15) -> 500 | AC15: =AB15/12 -> 41.666667 | AD15: =AC15 -> 41.666667 | AE15: =AD15 -> 41.666667 | AF15: =AE15 -> 41.666667 | AG15: =AF15 -> 41.666667 | AH15: =AG15 -> 41.666667 | AI15: =AH15 -> 41.666667 | AJ15: =AI15 -> 41.666667 | AK15: =AJ15 -> 41.666667 | ... AN15: =AM15 -> 41.666667 | AO15: =SUM(AC15:AN15) -> 500 | AP15: =AO15 -> 500 | AQ15: =AP15 -> 500 | AR15: =AQ15 -> 500 | AS15: =AR15 -> 500 | AT15: =AS15 -> 500 | AU15: =AT15 -> 500 | AV15: =AU15 -> 500 | AW15: =AV15 -> 500 | ... BC15: =BB15 -> 500
A16: 1.9 | B16: Расходы по заработной плате | C16: 740.74074 | D16: 740.74074 | E16: 740.74074 | F16: 740.74074 | G16: 740.74074 | H16: 740.74074 | I16: 740.74074 | J16: 740.74074 | K16: 740.74074 | L16: 740.74074 | M16: 740.74074 | N16: 740.74074 | O16: =SUM(C16:N16) -> 8888.8889 | P16: =O16/12 -> 740.74074 | Q16: =P16 -> 740.74074 | R16: =Q16 -> 740.74074 | S16: =R16 -> 740.74074 | T16: =S16 -> 740.74074 | U16: =T16 -> 740.74074 | V16: =U16 -> 740.74074 | W16: =V16 -> 740.74074 | X16: =W16 -> 740.74074 | ... AA16: =Z16 -> 740.74074 | AB16: =SUM(P16:AA16) -> 8888.8889 | AC16: =AB16/12 -> 740.74074 | AD16: =AC16 -> 740.74074 | AE16: =AD16 -> 740.74074 | AF16: =AE16 -> 740.74074 | AG16: =AF16 -> 740.74074 | AH16: =AG16 -> 740.74074 | AI16: =AH16 -> 740.74074 | AJ16: =AI16 -> 740.74074 | AK16: =AJ16 -> 740.74074 | ... AN16: =AM16 -> 740.74074 | AO16: =SUM(AC16:AN16) -> 8888.8889 | AP16: =AO16 -> 8888.8889 | AQ16: =AP16 -> 8888.8889 | AR16: =AQ16 -> 8888.8889 | AS16: =AR16 -> 8888.8889 | AT16: =AS16 -> 8888.8889 | AU16: =AT16 -> 8888.8889 | AV16: =AU16 -> 8888.8889 | AW16: =AV16 -> 8888.8889 | ... BC16: =BB16 -> 8888.8889
A17: 1.10 | B17: Социальные отчисления | C17: 17.677178 | D17: 17.677178 | E17: 17.677178 | F17: 17.677178 | G17: 17.677178 | H17: 17.677178 | I17: 17.677178 | J17: 17.677178 | K17: 17.677178 | L17: 17.677178 | M17: 17.677178 | N17: 17.677178 | O17: =SUM(C17:N17) -> 212.12613 | P17: =O17/12 -> 17.677178 | Q17: =P17 -> 17.677178 | R17: =Q17 -> 17.677178 | S17: =R17 -> 17.677178 | T17: =S17 -> 17.677178 | U17: =T17 -> 17.677178 | V17: =U17 -> 17.677178 | W17: =V17 -> 17.677178 | X17: =W17 -> 17.677178 | ... AA17: =Z17 -> 17.677178 | AB17: =SUM(P17:AA17) -> 212.12613 | AC17: =AB17/12 -> 17.677178 | AD17: =AC17 -> 17.677178 | AE17: =AD17 -> 17.677178 | AF17: =AE17 -> 17.677178 | AG17: =AF17 -> 17.677178 | AH17: =AG17 -> 17.677178 | AI17: =AH17 -> 17.677178 | AJ17: =AI17 -> 17.677178 | AK17: =AJ17 -> 17.677178 | ... AN17: =AM17 -> 17.677178 | AO17: =SUM(AC17:AN17) -> 212.12613 | AP17: =AO17 -> 212.12613 | AQ17: =AP17 -> 212.12613 | AR17: =AQ17 -> 212.12613 | AS17: =AR17 -> 212.12613 | AT17: =AS17 -> 212.12613 | AU17: =AT17 -> 212.12613 | AV17: =AU17 -> 212.12613 | AW17: =AV17 -> 212.12613 | ... BC17: =BB17 -> 212.12613
A18: 1.11 | B18: Социальный налог | C18: 45.656156 | D18: 45.656156 | E18: 45.656156 | F18: 45.656156 | G18: 45.656156 | H18: 45.656156 | I18: 45.656156 | J18: 45.656156 | K18: 45.656156 | L18: 45.656156 | M18: 45.656156 | N18: 45.656156 | O18: =SUM(C18:N18) -> 547.87387 | P18: =O18/12 -> 45.656156 | Q18: =P18 -> 45.656156 | R18: =Q18 -> 45.656156 | S18: =R18 -> 45.656156 | T18: =S18 -> 45.656156 | U18: =T18 -> 45.656156 | V18: =U18 -> 45.656156 | W18: =V18 -> 45.656156 | X18: =W18 -> 45.656156 | ... AA18: =Z18 -> 45.656156 | AB18: =SUM(P18:AA18) -> 547.87387 | AC18: =AB18/12 -> 45.656156 | AD18: =AC18 -> 45.656156 | AE18: =AD18 -> 45.656156 | AF18: =AE18 -> 45.656156 | AG18: =AF18 -> 45.656156 | AH18: =AG18 -> 45.656156 | AI18: =AH18 -> 45.656156 | AJ18: =AI18 -> 45.656156 | AK18: =AJ18 -> 45.656156 | ... AN18: =AM18 -> 45.656156 | AO18: =SUM(AC18:AN18) -> 547.87387 | AP18: =AO18 -> 547.87387 | AQ18: =AP18 -> 547.87387 | AR18: =AQ18 -> 547.87387 | AS18: =AR18 -> 547.87387 | AT18: =AS18 -> 547.87387 | AU18: =AT18 -> 547.87387 | AV18: =AU18 -> 547.87387 | AW18: =AV18 -> 547.87387 | ... BC18: =BB18 -> 547.87387
A19: 1.12 | B19: Страхование | C19: 66.666667 | D19: 66.666667 | E19: 66.666667 | F19: 66.666667 | G19: 66.666667 | H19: 66.666667 | I19: 66.666667 | J19: 66.666667 | K19: 66.666667 | L19: 66.666667 | M19: 66.666667 | N19: 66.666667 | O19: =SUM(C19:N19) -> 800 | P19: =O19/12 -> 66.666667 | Q19: =P19 -> 66.666667 | R19: =Q19 -> 66.666667 | S19: =R19 -> 66.666667 | T19: =S19 -> 66.666667 | U19: =T19 -> 66.666667 | V19: =U19 -> 66.666667 | W19: =V19 -> 66.666667 | X19: =W19 -> 66.666667 | ... AA19: =Z19 -> 66.666667 | AB19: =SUM(P19:AA19) -> 800 | AC19: =AB19/12 -> 66.666667 | AD19: =AC19 -> 66.666667 | AE19: =AD19 -> 66.666667 | AF19: =AE19 -> 66.666667 | AG19: =AF19 -> 66.666667 | AH19: =AG19 -> 66.666667 | AI19: =AH19 -> 66.666667 | AJ19: =AI19 -> 66.666667 | AK19: =AJ19 -> 66.666667 | ... AN19: =AM19 -> 66.666667 | AO19: =SUM(AC19:AN19) -> 800 | AP19: =AO19 -> 800 | AQ19: =AP19 -> 800 | AR19: =AQ19 -> 800 | AS19: =AR19 -> 800 | AT19: =AS19 -> 800 | AU19: =AT19 -> 800 | AV19: =AU19 -> 800 | AW19: =AV19 -> 800 | ... BC19: =BB19 -> 800
A20: 1.13 | B20: Консалтинговые услуги | C20: 892.85714 | D20: 892.85714 | E20: 892.85714 | F20: 892.85714 | G20: 892.85714 | H20: 892.85714 | I20: 892.85714 | J20: 892.85714 | K20: 892.85714 | L20: 892.85714 | M20: 892.85714 | N20: 892.85714 | O20: =SUM(C20:N20) -> 10714.286 | P20: =(O20/12)*(1+Panel!$B$43) -> 997.32143 | Q20: =P20 -> 997.32143 | R20: =Q20 -> 997.32143 | S20: =R20 -> 997.32143 | T20: =S20 -> 997.32143 | U20: =T20 -> 997.32143 | V20: =U20 -> 997.32143 | W20: =V20 -> 997.32143 | X20: =W20 -> 997.32143 | ... AA20: =Z20 -> 997.32143 | AB20: =SUM(P20:AA20) -> 11967.857 | AC20: =(AB20/12)*(1+Panel!$B$43) -> 1114.008 | AD20: =AC20 -> 1114.008 | AE20: =AD20 -> 1114.008 | AF20: =AE20 -> 1114.008 | AG20: =AF20 -> 1114.008 | AH20: =AG20 -> 1114.008 | AI20: =AH20 -> 1114.008 | AJ20: =AI20 -> 1114.008 | AK20: =AJ20 -> 1114.008 | ... AN20: =AM20 -> 1114.008 | AO20: =SUM(AC20:AN20) -> 13368.096 | AP20: =(AO20)*(1+Panel!$B$43) -> 14932.164 | AQ20: =(AP20)*(1+Panel!$B$43) -> 16679.227 | AR20: =(AQ20)*(1+Panel!$B$43) -> 18630.696 | AS20: =(AR20)*(1+Panel!$B$43) -> 20810.488 | AT20: =(AS20)*(1+Panel!$B$43) -> 23245.315 | AU20: =(AT20)*(1+Panel!$B$43) -> 25965.017 | AV20: =(AU20)*(1+Panel!$B$43) -> 29002.924 | AW20: =(AV20)*(1+Panel!$B$43) -> 32396.266 | ... BC20: =(BB20)*(1+Panel!$B$43) -> 62923.663
A21: 1.14 | B21: Услуги банка | C21: 83.333333 | D21: 83.333333 | E21: 83.333333 | F21: 83.333333 | G21: 83.333333 | H21: 83.333333 | I21: 83.333333 | J21: 83.333333 | K21: 83.333333 | L21: 83.333333 | M21: 83.333333 | N21: 83.333333 | O21: =SUM(C21:N21) -> 1000 | P21: =(O21/12)*(1+Panel!$B$43) -> 93.083333 | Q21: =P21 -> 93.083333 | R21: =Q21 -> 93.083333 | S21: =R21 -> 93.083333 | T21: =S21 -> 93.083333 | U21: =T21 -> 93.083333 | V21: =U21 -> 93.083333 | W21: =V21 -> 93.083333 | X21: =W21 -> 93.083333 | ... AA21: =Z21 -> 93.083333 | AB21: =SUM(P21:AA21) -> 1117 | AC21: =(AB21/12)*(1+Panel!$B$43) -> 103.97408 | AD21: =AC21 -> 103.97408 | AE21: =AD21 -> 103.97408 | AF21: =AE21 -> 103.97408 | AG21: =AF21 -> 103.97408 | AH21: =AG21 -> 103.97408 | AI21: =AH21 -> 103.97408 | AJ21: =AI21 -> 103.97408 | AK21: =AJ21 -> 103.97408 | ... AN21: =AM21 -> 103.97408 | AO21: =SUM(AC21:AN21) -> 1247.689 | AP21: =(AO21)*(1+Panel!$B$43) -> 1393.6686 | AQ21: =(AP21)*(1+Panel!$B$43) -> 1556.7278 | AR21: =(AQ21)*(1+Panel!$B$43) -> 1738.865 | AS21: =(AR21)*(1+Panel!$B$43) -> 1942.3122 | AT21: =(AS21)*(1+Panel!$B$43) -> 2169.5627 | AU21: =(AT21)*(1+Panel!$B$43) -> 2423.4016 | AV21: =(AU21)*(1+Panel!$B$43) -> 2706.9396 | AW21: =(AV21)*(1+Panel!$B$43) -> 3023.6515 | ... BC21: =(BB21)*(1+Panel!$B$43) -> 5872.8752
A22: 1.15 | B22: Услуги сотовой связи | C22: 4.0117925 | D22: 4.0117925 | E22: 4.0117925 | F22: 4.0117925 | G22: 4.0117925 | H22: 4.0117925 | I22: 4.0117925 | J22: 4.0117925 | K22: 4.0117925 | L22: 4.0117925 | M22: 4.0117925 | N22: 4.0117925 | O22: =SUM(C22:N22) -> 48.14151 | P22: =(O22/12)*(1+Panel!$B$43) -> 4.4811722 | Q22: =P22 -> 4.4811722 | R22: =Q22 -> 4.4811722 | S22: =R22 -> 4.4811722 | T22: =S22 -> 4.4811722 | U22: =T22 -> 4.4811722 | V22: =U22 -> 4.4811722 | W22: =V22 -> 4.4811722 | X22: =W22 -> 4.4811722 | ... AA22: =Z22 -> 4.4811722 | AB22: =SUM(P22:AA22) -> 53.774067 | AC22: =(AB22/12)*(1+Panel!$B$43) -> 5.0054694 | AD22: =AC22 -> 5.0054694 | AE22: =AD22 -> 5.0054694 | AF22: =AE22 -> 5.0054694 | AG22: =AF22 -> 5.0054694 | AH22: =AG22 -> 5.0054694 | AI22: =AH22 -> 5.0054694 | AJ22: =AI22 -> 5.0054694 | AK22: =AJ22 -> 5.0054694 | ... AN22: =AM22 -> 5.0054694 | AO22: =SUM(AC22:AN22) -> 60.065632 | AP22: =(AO22)*(1+Panel!$B$43) -> 67.093311 | AQ22: =(AP22)*(1+Panel!$B$43) -> 74.943229 | AR22: =(AQ22)*(1+Panel!$B$43) -> 83.711587 | AS22: =(AR22)*(1+Panel!$B$43) -> 93.505842 | AT22: =(AS22)*(1+Panel!$B$43) -> 104.44603 | AU22: =(AT22)*(1+Panel!$B$43) -> 116.66621 | AV22: =(AU22)*(1+Panel!$B$43) -> 130.31616 | AW22: =(AV22)*(1+Panel!$B$43) -> 145.56315 | ... BC22: =(BB22)*(1+Panel!$B$43) -> 282.72908
A23: 1.16 | B23: Аренда | C23: 89.285714 | D23: 89.285714 | E23: 89.285714 | F23: 89.285714 | G23: 89.285714 | H23: 89.285714 | I23: 89.285714 | J23: 89.285714 | K23: 89.285714 | L23: 89.285714 | M23: 89.285714 | N23: 89.285714 | O23: =SUM(C23:N23) -> 1071.4286 | P23: =(O23/12)*(1+Panel!$B$43) -> 99.732143 | Q23: =P23 -> 99.732143 | R23: =Q23 -> 99.732143 | S23: =R23 -> 99.732143 | T23: =S23 -> 99.732143 | U23: =T23 -> 99.732143 | V23: =U23 -> 99.732143 | W23: =V23 -> 99.732143 | X23: =W23 -> 99.732143 | ... AA23: =Z23 -> 99.732143 | AB23: =SUM(P23:AA23) -> 1196.7857 | AC23: =(AB23/12)*(1+Panel!$B$43) -> 111.4008 | AD23: =AC23 -> 111.4008 | AE23: =AD23 -> 111.4008 | AF23: =AE23 -> 111.4008 | AG23: =AF23 -> 111.4008 | AH23: =AG23 -> 111.4008 | AI23: =AH23 -> 111.4008 | AJ23: =AI23 -> 111.4008 | AK23: =AJ23 -> 111.4008 | ... AN23: =AM23 -> 111.4008 | AO23: =SUM(AC23:AN23) -> 1336.8096 | AP23: =(AO23)*(1+Panel!$B$43) -> 1493.2164 | AQ23: =(AP23)*(1+Panel!$B$43) -> 1667.9227 | AR23: =(AQ23)*(1+Panel!$B$43) -> 1863.0696 | AS23: =(AR23)*(1+Panel!$B$43) -> 2081.0488 | AT23: =(AS23)*(1+Panel!$B$43) -> 2324.5315 | AU23: =(AT23)*(1+Panel!$B$43) -> 2596.5017 | AV23: =(AU23)*(1+Panel!$B$43) -> 2900.2924 | AW23: =(AV23)*(1+Panel!$B$43) -> 3239.6266 | ... BC23: =(BB23)*(1+Panel!$B$43) -> 6292.3663
B24: Итого | C24: =SUM(C8:C23) -> 2004.1208 | D24: =SUM(D8:D23) -> 2004.1208 | E24: =SUM(E8:E23) -> 2004.1208 | F24: =SUM(F8:F23) -> 2004.1208 | G24: =SUM(G8:G23) -> 2004.1208 | H24: =SUM(H8:H23) -> 2004.1208 | I24: =SUM(I8:I23) -> 2004.1208 | J24: =SUM(J8:J23) -> 2004.1208 | ... BC24: =SUM(BC8:BC23) -> 87132.749
A27: РАСЧЕТ ЕЖЕМЕСЯЧНОГО ФОНДА ОПЛАТЫ ТРУДА АДМИНИСТРАТИВНОГО ПЕРСОНАЛА,
